Workbook

Sheet README
B2: Stock Market Analysis Dashboard
B6: Sumber data:
B7: Dataset bergaya Kaggle 'Stock Market Dataset' (OHLCV harian, 8 ticker, tahun 2024).
B8: Catatan data:
B9: Data pada sheet Raw_Data adalah DATA SIMULASI (synthetic) yang meniru struktur dan
B10: karakteristik dataset asli Kaggle, dibuat agar workbook ini bisa didemokan end-to-end.
B11: Untuk versi produksi, ganti isi sheet Raw_Data dengan hasil query SQL dari data riil
B12: (lihat folder /sql pada repository project ini).
B14: Alur project:
B15: 1. Data cleaning & staging -> sql/01_schema_and_cleaning.sql
B16: 2. Analisis SQL (window functions, CTE) -> sql/02_analysis_queries.sql
B17: 3. Hasil query diringkas & divisualisasikan di workbook Excel ini
... B30: 4. Kapan terjadi lonjakan volume yang mengindikasikan berita besar?

Sheet Dashboard
B1: Stock Market Analysis - Dashboard Ringkasan
B3: Periode: Januari - Desember 2024 | 8 ticker, 6 sektor
B5: Ticker Paling Volatile | E5: Ticker Paling Stabil | H5: Max Drawdown Terdalam | K5: Return Tertinggi (Total 2024)
B6: =INDEX(Ticker_Summary!A:A,MATCH(1,Ticker_Summary!I:I,0)) -> TSLA | E6: =INDEX(Ticker_Summary!A:A,MATCH(8,Ticker_Summary!I:I,0)) -> KO | H6: =INDEX(Ticker_Summary!A:A,MATCH(MIN(Ticker_Summary!E:E),Ticker_Summary!E:E,0)) -> TSLA | K6: =INDEX(Ticker_Summary!A:A,MATCH(MAX(Ticker_Summary!H:H),Ticker_Summary!H:H,0)) -> AAPL
B8: =INDEX(Ticker_Summary!D:D,MATCH(1,Ticker_Summary!I:I,0)) -> 3.5427906 | E8: =INDEX(Ticker_Summary!D:D,MATCH(8,Ticker_Summary!I:I,0)) -> 1.2892033 | H8: =MIN(Ticker_Summary!E:E) -> -59.185294 | K8: =MAX(Ticker_Summary!H:H) -> 77.703215

Sheet Raw_Data
A1: Ticker | B1: Sector | C1: Date | D1: Open | E1: High | F1: Low | G1: Close | H1: Adj_Close | I1: Volume | J1: Daily_Return_% | K1: MA_20 | L1: MA_50 | M1: Running_Peak | N1: Drawdown_% | O1: Month
A2: AAPL | B2: Technology | C2: 2024-01-01 | D2: 170 | E2: 171.46 | F2: 169.24 | G2: 171.37 | H2: 171.37 | I2: 8765365 | M2: =MAX(G2:G2) -> 171.37 | N2: =(G2-M2)/M2*100 -> 0 | O2: =TEXT(C2,"yyyy-mm") -> 2024-01
A3: AAPL | B3: Technology | C3: 2024-01-02 | D3: 171.37 | E3: 172.88 | F3: 171.05 | G3: 172.19 | H3: 172.19 | I3: 9302144 | J3: =IFERROR((G3-G2)/G2*100,"") -> 0.47849682 | M3: =MAX(G2:G3) -> 172.19 | N3: =(G3-M3)/M3*100 -> 0 | O3: =TEXT(C3,"yyyy-mm") -> 2024-01
A4: AAPL | B4: Technology | C4: 2024-01-03 | D4: 172.19 | E4: 172.51 | F4: 169.31 | G4: 171.1 | H4: 171.1 | I4: 10280887 | J4: =IFERROR((G4-G3)/G3*100,"") -> -0.63302166 | M4: =MAX(G2:G4) -> 172.19 | N4: =(G4-M4)/M4*100 -> -0.63302166 | O4: =TEXT(C4,"yyyy-mm") -> 2024-01
A5: AAPL | B5: Technology | C5: 2024-01-04 | D5: 171.1 | E5: 174.35 | F5: 170.47 | G5: 173.29 | H5: 173.29 | I5: 4610471 | J5: =IFERROR((G5-G4)/G4*100,"") -> 1.2799532 | M5: =MAX(G2:G5) -> 173.29 | N5: =(G5-M5)/M5*100 -> 0 | O5: =TEXT(C5,"yyyy-mm") -> 2024-01
A6: AAPL | B6: Technology | C6: 2024-01-05 | D6: 173.29 | E6: 177.37 | F6: 171.52 | G6: 177.21 | H6: 177.21 | I6: 8946159 | J6: =IFERROR((G6-G5)/G5*100,"") -> 2.262104 | M6: =MAX(G2:G6) -> 177.21 | N6: =(G6-M6)/M6*100 -> 0 | O6: =TEXT(C6,"yyyy-mm") -> 2024-01
A7: AAPL | B7: Technology | C7: 2024-01-08 | D7: 177.21 | E7: 178 | F7: 176.78 | G7: 177.64 | H7: 177.64 | I7: 7299935 | J7: =IFERROR((G7-G6)/G6*100,"") -> 0.24264996 | M7: =MAX(G2:G7) -> 177.64 | N7: =(G7-M7)/M7*100 -> 0 | O7: =TEXT(C7,"yyyy-mm") -> 2024-01
A8: AAPL | B8: Technology | C8: 2024-01-09 | D8: 177.64 | E8: 178.95 | F8: 175.77 | G8: 176.14 | H8: 176.14 | I8: 7986733 | J8: =IFERROR((G8-G7)/G7*100,"") -> -0.84440441 | M8: =MAX(G2:G8) -> 177.64 | N8: =(G8-M8)/M8*100 -> -0.84440441 | O8: =TEXT(C8,"yyyy-mm") -> 2024-01
A9: AAPL | B9: Technology | C9: 2024-01-10 | D9: 176.14 | E9: 176.42 | F9: 175.49 | G9: 175.64 | H9: 175.64 | I9: 3296791 | J9: =IFERROR((G9-G8)/G8*100,"") -> -0.28386511 | M9: =MAX(G2:G9) -> 177.64 | N9: =(G9-M9)/M9*100 -> -1.1258726 | O9: =TEXT(C9,"yyyy-mm") -> 2024-01
A10: AAPL | B10: Technology | C10: 2024-01-11 | D10: 175.64 | E10: 175.78 | F10: 172.1 | G10: 172.25 | H10: 172.25 | I10: 10116226 | J10: =IFERROR((G10-G9)/G9*100,"") -> -1.9300843 | M10: =MAX(G2:G10) -> 177.64 | N10: =(G10-M10)/M10*100 -> -3.0342265 | O10: =TEXT(C10,"yyyy-mm") -> 2024-01
A11: AAPL | B11: Technology | C11: 2024-01-12 | D11: 172.25 | E11: 173.34 | F11: 169.43 | G11: 169.74 | H11: 169.74 | I11: 10537093 | J11: =IFERROR((G11-G10)/G10*100,"") -> -1.4571843 | M11: =MAX(G2:G11) -> 177.64 | N11: =(G11-M11)/M11*100 -> -4.4471966 | O11: =TEXT(C11,"yyyy-mm") -> 2024-01
A12: AAPL | B12: Technology | C12: 2024-01-15 | D12: 169.74 | E12: 171.92 | F12: 169.35 | G12: 170.72 | H12: 170.72 | I12: 10130596 | J12: =IFERROR((G12-G11)/G11*100,"") -> 0.5773536 | M12: =MAX(G2:G12) -> 177.64 | N12: =(G12-M12)/M12*100 -> -3.895519 | O12: =TEXT(C12,"yyyy-mm") -> 2024-01
A13: AAPL | B13: Technology | C13: 2024-01-16 | D13: 170.72 | E13: 173.64 | F13: 170.15 | G13: 173.11 | H13: 173.11 | I13: 7257890 | J13: =IFERROR((G13-G12)/G12*100,"") -> 1.3999531 | M13: =MAX(G2:G13) -> 177.64 | N13: =(G13-M13)/M13*100 -> -2.5501013 | O13: =TEXT(C13,"yyyy-mm") -> 2024-01
A14: AAPL | B14: Technology | C14: 2024-01-17 | D14: 173.11 | E14: 174.76 | F14: 172.99 | G14: 174.08 | H14: 174.08 | I14: 7015080 | J14: =IFERROR((G14-G13)/G13*100,"") -> 0.56033736 | M14: =MAX(G2:G14) -> 177.64 | N14: =(G14-M14)/M14*100 -> -2.0040531 | O14: =TEXT(C14,"yyyy-mm") -> 2024-01
A15: AAPL | B15: Technology | C15: 2024-01-18 | D15: 174.08 | E15: 177.9 | F15: 174.03 | G15: 177.26 | H15: 177.26 | I15: 10408478 | J15: =IFERROR((G15-G14)/G14*100,"") -> 1.8267463 | M15: =MAX(G2:G15) -> 177.64 | N15: =(G15-M15)/M15*100 -> -0.21391578 | O15: =TEXT(C15,"yyyy-mm") -> 2024-01
A16: AAPL | B16: Technology | C16: 2024-01-19 | D16: 177.26 | E16: 178.79 | F16: 176.2 | G16: 178.33 | H16: 178.33 | I16: 8811635 | J16: =IFERROR((G16-G15)/G15*100,"") -> 0.60363308 | M16: =MAX(G2:G16) -> 178.33 | N16: =(G16-M16)/M16*100 -> 0 | O16: =TEXT(C16,"yyyy-mm") -> 2024-01
A17: AAPL | B17: Technology | C17: 2024-01-22 | D17: 178.33 | E17: 188.15 | F17: 178.27 | G17: 187.46 | H17: 187.46 | I17: 19143284 | J17: =IFERROR((G17-G16)/G16*100,"") -> 5.1197219 | M17: =MAX(G2:G17) -> 187.46 | N17: =(G17-M17)/M17*100 -> 0 | O17: =TEXT(C17,"yyyy-mm") -> 2024-01
A18: AAPL | B18: Technology | C18: 2024-01-23 | D18: 187.46 | E18: 190.12 | F18: 186.35 | G18: 190.11 | H18: 190.11 | I18: 6756151 | J18: =IFERROR((G18-G17)/G17*100,"") -> 1.4136349 | M18: =MAX(G2:G18) -> 190.11 | N18: =(G18-M18)/M18*100 -> 0 | O18: =TEXT(C18,"yyyy-mm") -> 2024-01
A19: AAPL | B19: Technology | C19: 2024-01-24 | D19: 190.11 | E19: 190.49 | F19: 187.54 | G19: 187.92 | H19: 187.92 | I19: 10779647 | J19: =IFERROR((G19-G18)/G18*100,"") -> -1.1519647 | M19: =MAX(G2:G19) -> 190.11 | N19: =(G19-M19)/M19*100 -> -1.1519647 | O19: =TEXT(C19,"yyyy-mm") -> 2024-01
A20: AAPL | B20: Technology | C20: 2024-01-25 | D20: 187.92 | E20: 188.99 | F20: 187.85 | G20: 188.76 | H20: 188.76 | I20: 10324747 | J20: =IFERROR((G20-G19)/G19*100,"") -> 0.44699872 | M20: =MAX(G2:G20) -> 190.11 | N20: =(G20-M20)/M20*100 -> -0.7101152 | O20: =TEXT(C20,"yyyy-mm") -> 2024-01
A21: AAPL | B21: Technology | C21: 2024-01-26 | D21: 188.76 | E21: 189 | F21: 185.93 | G21: 186.88 | H21: 186.88 | I21: 7299313 | J21: =IFERROR((G21-G20)/G20*100,"") -> -0.99597372 | K21: =AVERAGE(G2:G21) -> 177.56 | M21: =MAX(G2:G21) -> 190.11 | N21: =(G21-M21)/M21*100 -> -1.6990164 | O21: =TEXT(C21,"yyyy-mm") -> 2024-01
A22: AAPL | B22: Technology | C22: 2024-01-29 | D22: 186.88 | E22: 187.14 | F22: 179.3 | G22: 179.55 | H22: 179.55 | I22: 6074534 | J22: =IFERROR((G22-G21)/G21*100,"") -> -3.9223031 | K22: =AVERAGE(G3:G22) -> 177.969 | M22: =MAX(G2:G22) -> 190.11 | N22: =(G22-M22)/M22*100 -> -5.5546789 | O22: =TEXT(C22,"yyyy-mm") -> 2024-01
A23: AAPL | B23: Technology | C23: 2024-01-30 | D23: 179.55 | E23: 179.84 | F23: 178.55 | G23: 179.22 | H23: 179.22 | I23: 11369500 | J23: =IFERROR((G23-G22)/G22*100,"") -> -0.18379282 | K23: =AVERAGE(G4:G23) -> 178.3205 | M23: =MAX(G2:G23) -> 190.11 | N23: =(G23-M23)/M23*100 -> -5.7282626 | O23: =TEXT(C23,"yyyy-mm") -> 2024-01
A24: AAPL | B24: Technology | C24: 2024-01-31 | D24: 179.22 | E24: 180.48 | F24: 179.18 | G24: 179.28 | H24: 179.28 | I24: 13911781 | J24: =IFERROR((G24-G23)/G23*100,"") -> 0.033478406 | K24: =AVERAGE(G5:G24) -> 178.7295 | M24: =MAX(G2:G24) -> 190.11 | N24: =(G24-M24)/M24*100 -> -5.6967019 | O24: =TEXT(C24,"yyyy-mm") -> 2024-01
A25: AAPL | B25: Technology | C25: 2024-02-01 | D25: 179.28 | E25: 179.5 | F25: 178.63 | G25: 178.87 | H25: 178.87 | I25: 7982287 | J25: =IFERROR((G25-G24)/G24*100,"") -> -0.22869255 | K25: =AVERAGE(G6:G25) -> 179.0085 | M25: =MAX(G2:G25) -> 190.11 | N25: =(G25-M25)/M25*100 -> -5.9123665 | O25: =TEXT(C25,"yyyy-mm") -> 2024-02
A26: AAPL | B26: Technology | C26: 2024-02-02 | D26: 178.87 | E26: 181.87 | F26: 178.31 | G26: 181.04 | H26: 181.04 | I26: 5817470 | J26: =IFERROR((G26-G25)/G25*100,"") -> 1.2131716 | K26: =AVERAGE(G7:G26) -> 179.2 | M26: =MAX(G2:G26) -> 190.11 | N26: =(G26-M26)/M26*100 -> -4.7709221 | O26: =TEXT(C26,"yyyy-mm") -> 2024-02
A27: AAPL | B27: Technology | C27: 2024-02-05 | D27: 181.04 | E27: 185.99 | F27: 180.4 | G27: 184.96 | H27: 184.96 | I27: 8184547 | J27: =IFERROR((G27-G26)/G26*100,"") -> 2.1652673 | K27: =AVERAGE(G8:G27) -> 179.566 | M27: =MAX(G2:G27) -> 190.11 | N27: =(G27-M27)/M27*100 -> -2.708958 | O27: =TEXT(C27,"yyyy-mm") -> 2024-02
A28: AAPL | B28: Technology | C28: 2024-02-06 | D28: 184.96 | E28: 185.64 | F28: 183.62 | G28: 183.7 | H28: 183.7 | I28: 6791658 | J28: =IFERROR((G28-G27)/G27*100,"") -> -0.68122837 | K28: =AVERAGE(G9:G28) -> 179.944 | M28: =MAX(G2:G28) -> 190.11 | N28: =(G28-M28)/M28*100 -> -3.3717322 | O28: =TEXT(C28,"yyyy-mm") -> 2024-02
A29: AAPL | B29: Technology | C29: 2024-02-07 | D29: 183.7 | E29: 183.75 | F29: 179.15 | G29: 179.54 | H29: 179.54 | I29: 5804741 | J29: =IFERROR((G29-G28)/G28*100,"") -> -2.2645618 | K29: =AVERAGE(G10:G29) -> 180.139 | M29: =MAX(G2:G29) -> 190.11 | N29: =(G29-M29)/M29*100 -> -5.559939 | O29: =TEXT(C29,"yyyy-mm") -> 2024-02
A30: AAPL | B30: Technology | C30: 2024-02-08 | D30: 179.54 | E30: 181.43 | F30: 178.97 | G30: 181.31 | H30: 181.31 | I30: 7227052 | J30: =IFERROR((G30-G29)/G29*100,"") -> 0.98585273 | K30: =AVERAGE(G11:G30) -> 180.592 | M30: =MAX(G2:G30) -> 190.11 | N30: =(G30-M30)/M30*100 -> -4.6288991 | O30: =TEXT(C30,"yyyy-mm") -> 2024-02
A31: AAPL | B31: Technology | C31: 2024-02-09 | D31: 181.31 | E31: 184.54 | F31: 180.33 | G31: 183.64 | H31: 183.64 | I31: 14093990 | J31: =IFERROR((G31-G30)/G30*100,"") -> 1.2850918 | K31: =AVERAGE(G12:G31) -> 181.287 | M31: =MAX(G2:G31) -> 190.11 | N31: =(G31-M31)/M31*100 -> -3.4032928 | O31: =TEXT(C31,"yyyy-mm") -> 2024-02
A32: AAPL | B32: Technology | C32: 2024-02-12 | D32: 183.64 | E32: 183.79 | F32: 182.66 | G32: 182.85 | H32: 182.85 | I32: 9876374 | J32: =IFERROR((G32-G31)/G31*100,"") -> -0.4301895 | K32: =AVERAGE(G13:G32) -> 181.8935 | M32: =MAX(G2:G32) -> 190.11 | N32: =(G32-M32)/M32*100 -> -3.8188417 | O32: =TEXT(C32,"yyyy-mm") -> 2024-02
A33: AAPL | B33: Technology | C33: 2024-02-13 | D33: 182.85 | E33: 183.82 | F33: 179.13 | G33: 179.57 | H33: 179.57 | I33: 10920969 | J33: =IFERROR((G33-G32)/G32*100,"") -> -1.7938201 | K33: =AVERAGE(G14:G33) -> 182.2165 | M33: =MAX(G2:G33) -> 190.11 | N33: =(G33-M33)/M33*100 -> -5.5441586 | O33: =TEXT(C33,"yyyy-mm") -> 2024-02
A34: AAPL | B34: Technology | C34: 2024-02-14 | D34: 179.57 | E34: 196.68 | F34: 179.47 | G34: 196.02 | H34: 196.02 | I34: 9724809 | J34: =IFERROR((G34-G33)/G33*100,"") -> 9.160773 | K34: =AVERAGE(G15:G34) -> 183.3135 | M34: =MAX(G2:G34) -> 196.02 | N34: =(G34-M34)/M34*100 -> 0 | O34: =TEXT(C34,"yyyy-mm") -> 2024-02
A35: AAPL | B35: Technology | C35: 2024-02-15 | D35: 196.02 | E35: 196.42 | F35: 194.96 | G35: 196.12 | H35: 196.12 | I35: 6237085 | J35: =IFERROR((G35-G34)/G34*100,"") -> 0.051015203 | K35: =AVERAGE(G16:G35) -> 184.2565 | M35: =MAX(G2:G35) -> 196.12 | N35: =(G35-M35)/M35*100 -> 0 | O35: =TEXT(C35,"yyyy-mm") -> 2024-02
A36: AAPL | B36: Technology | C36: 2024-02-16 | D36: 196.12 | E36: 196.99 | F36: 191.66 | G36: 193.41 | H36: 193.41 | I36: 8352739 | J36: =IFERROR((G36-G35)/G35*100,"") -> -1.3818071 | K36: =AVERAGE(G17:G36) -> 185.0105 | M36: =MAX(G2:G36) -> 196.12 | N36: =(G36-M36)/M36*100 -> -1.3818071 | O36: =TEXT(C36,"yyyy-mm") -> 2024-02
A37: AAPL | B37: Technology | C37: 2024-02-19 | D37: 193.41 | E37: 196.27 | F37: 192.71 | G37: 195.1 | H37: 195.1 | I37: 7928659 | J37: =IFERROR((G37-G36)/G36*100,"") -> 0.87379143 | K37: =AVERAGE(G18:G37) -> 185.3925 | M37: =MAX(G2:G37) -> 196.12 | N37: =(G37-M37)/M37*100 -> -0.52008974 | O37: =TEXT(C37,"yyyy-mm") -> 2024-02
A38: AAPL | B38: Technology | C38: 2024-02-20 | D38: 195.1 | E38: 195.76 | F38: 188.9 | G38: 189.55 | H38: 189.55 | I38: 8946415 | J38: =IFERROR((G38-G37)/G37*100,"") -> -2.844695 | K38: =AVERAGE(G19:G38) -> 185.3645 | M38: =MAX(G2:G38) -> 196.12 | N38: =(G38-M38)/M38*100 -> -3.3499898 | O38: =TEXT(C38,"yyyy-mm") -> 2024-02
A39: AAPL | B39: Technology | C39: 2024-02-21 | D39: 189.55 | E39: 190.84 | F39: 189.54 | G39: 189.65 | H39: 189.65 | I39: 8457436 | J39: =IFERROR((G39-G38)/G38*100,"") -> 0.052756529 | K39: =AVERAGE(G20:G39) -> 185.451 | M39: =MAX(G2:G39) -> 196.12 | N39: =(G39-M39)/M39*100 -> -3.2990006 | O39: =TEXT(C39,"yyyy-mm") -> 2024-02
A40: AAPL | B40: Technology | C40: 2024-02-22 | D40: 189.65 | E40: 191.75 | F40: 189.55 | G40: 191.49 | H40: 191.49 | I40: 8819817 | J40: =IFERROR((G40-G39)/G39*100,"") -> 0.97020828 | K40: =AVERAGE(G21:G40) -> 185.5875 | M40: =MAX(G2:G40) -> 196.12 | N40: =(G40-M40)/M40*100 -> -2.3607995 | O40: =TEXT(C40,"yyyy-mm") -> 2024-02
...

Sheet Ticker_Summary
A1: Ticker | B1: Sector | C1: Avg_Daily_Return_% | D1: Volatility_%(StdevPop) | E1: Max_Drawdown_% | F1: Best_Day_% | G1: Worst_Day_% | H1: Total_Return_% | I1: Volatility_Rank
A2: AAPL | B2: Technology | C2: =AVERAGE(Raw_Data!J3:J263) -> 0.2351789 | D2: =STDEV(Raw_Data!J3:J263) -> 1.7240151 | E2: =MIN(Raw_Data!N2:N263) -> -14.771323 | F2: =MAX(Raw_Data!J3:J263) -> 9.160773 | G2: =MIN(Raw_Data!J3:J263) -> -3.9223031 | H2: =(Raw_Data!G263-Raw_Data!G2)/Raw_Data!G2*100 -> 77.703215 | I2: =RANK(D2,$D$2:$D$9,0) -> 5
A3: JNJ | B3: Healthcare | C3: =AVERAGE(Raw_Data!J265:J525) -> -0.12473222 | D3: =STDEV(Raw_Data!J265:J525) -> 1.4815939 | E3: =MIN(Raw_Data!N264:N525) -> -37.389749 | F3: =MAX(Raw_Data!J265:J525) -> 7.4794388 | G3: =MIN(Raw_Data!J265:J525) -> -8.94136 | H3: =(Raw_Data!G525-Raw_Data!G264)/Raw_Data!G264*100 -> -29.877327 | I3: =RANK(D3,$D$2:$D$9,0) -> 7
A4: JPM | B4: Financials | C4: =AVERAGE(Raw_Data!J527:J787) -> 0.066863162 | D4: =STDEV(Raw_Data!J527:J787) -> 1.8949963 | E4: =MIN(Raw_Data!N526:N787) -> -24.363284 | F4: =MAX(Raw_Data!J527:J787) -> 8.5032482 | G4: =MIN(Raw_Data!J527:J787) -> -9.0135233 | H4: =(Raw_Data!G787-Raw_Data!G526)/Raw_Data!G526*100 -> 13.644761 | I4: =RANK(D4,$D$2:$D$9,0) -> 4
A5: KO | B5: Consumer Staples | C5: =AVERAGE(Raw_Data!J789:J1049) -> -0.046518507 | D5: =STDEV(Raw_Data!J789:J1049) -> 1.2892033 | E5: =MIN(Raw_Data!N788:N1049) -> -20.335852 | F5: =MAX(Raw_Data!J789:J1049) -> 6.4490913 | G5: =MIN(Raw_Data!J789:J1049) -> -8.8568684 | H5: =(Raw_Data!G1049-Raw_Data!G788)/Raw_Data!G788*100 -> -13.361848 | I5: =RANK(D5,$D$2:$D$9,0) -> 8
A6: MSFT | B6: Technology | C6: =AVERAGE(Raw_Data!J1051:J1311) -> 0.1493793 | D6: =STDEV(Raw_Data!J1051:J1311) -> 1.6482589 | E6: =MIN(Raw_Data!N1050:N1311) -> -14.703435 | F6: =MAX(Raw_Data!J1051:J1311) -> 8.1148031 | G6: =MIN(Raw_Data!J1051:J1311) -> -4.3938091 | H6: =(Raw_Data!G1311-Raw_Data!G1050)/Raw_Data!G1050*100 -> 42.589555 | I6: =RANK(D6,$D$2:$D$9,0) -> 6
A7: NVDA | B7: Technology | C7: =AVERAGE(Raw_Data!J1313:J1573) -> 0.21879283 | D7: =STDEV(Raw_Data!J1313:J1573) -> 3.0273136 | E7: =MIN(Raw_Data!N1312:N1573) -> -34.848615 | F7: =MAX(Raw_Data!J1313:J1573) -> 8.0276558 | G7: =MIN(Raw_Data!J1313:J1573) -> -12.566267 | H7: =(Raw_Data!G1573-Raw_Data!G1312)/Raw_Data!G1312*100 -> 56.975744 | I7: =RANK(D7,$D$2:$D$9,0) -> 2
A8: TSLA | B8: Consumer Discretionary | C8: =AVERAGE(Raw_Data!J1575:J1835) -> -0.16418755 | D8: =STDEV(Raw_Data!J1575:J1835) -> 3.5427906 | E8: =MIN(Raw_Data!N1574:N1835) -> -59.185294 | F8: =MAX(Raw_Data!J1575:J1835) -> 8.7297886 | G8: =MIN(Raw_Data!J1575:J1835) -> -10.304968 | H8: =(Raw_Data!G1835-Raw_Data!G1574)/Raw_Data!G1574*100 -> -44.758545 | I8: =RANK(D8,$D$2:$D$9,0) -> 1
A9: XOM | B9: Energy | C9: =AVERAGE(Raw_Data!J1837:J2097) -> 0.01021538 | D9: =STDEV(Raw_Data!J1837:J2097) -> 1.9778023 | E9: =MIN(Raw_Data!N1836:N2097) -> -27.029673 | F9: =MAX(Raw_Data!J1837:J2097) -> 9.049568 | G9: =MIN(Raw_Data!J1837:J2097) -> -9.670131 | H9: =(Raw_Data!G2097-Raw_Data!G1836)/Raw_Data!G1836*100 -> -2.4092802 | I9: =RANK(D9,$D$2:$D$9,0) -> 3

Sheet Quarterly_Return
A1: Ticker | B1: Sector | C1: Quarter | D1: Start_Close | E1: End_Close | F1: Return_% | G1: Rank_in_Quarter
A2: AAPL | B2: Technology | C2: 2024-Q1 | D2: =Raw_Data!G2 -> 171.37 | E2: =Raw_Data!G66 -> 238.75 | F2: =(E2-D2)/D2*100 -> 39.318434 | G2: =RANK(F2,$F$2:$F$9,0) -> 1
A3: JNJ | B3: Healthcare | C3: 2024-Q1 | D3: =Raw_Data!G264 -> 160.59 | E3: =Raw_Data!G328 -> 129.6 | F3: =(E3-D3)/D3*100 -> -19.29759 | G3: =RANK(F3,$F$2:$F$9,0) -> 6
A4: JPM | B4: Financials | C4: 2024-Q1 | D4: =Raw_Data!G526 -> 151.56 | E4: =Raw_Data!G590 -> 151.04 | F4: =(E4-D4)/D4*100 -> -0.34309844 | G4: =RANK(F4,$F$2:$F$9,0) -> 3
A5: KO | B5: Consumer Staples | C5: 2024-Q1 | D5: =Raw_Data!G788 -> 58.45 | E5: =Raw_Data!G852 -> 50.96 | F5: =(E5-D5)/D5*100 -> -12.814371 | G5: =RANK(F5,$F$2:$F$9,0) -> 5
A6: MSFT | B6: Technology | C6: 2024-Q1 | D6: =Raw_Data!G1050 -> 335.27 | E6: =Raw_Data!G1114 -> 323.35 | F6: =(E6-D6)/D6*100 -> -3.5553435 | G6: =RANK(F6,$F$2:$F$9,0) -> 4
A7: NVDA | B7: Technology | C7: 2024-Q1 | D7: =Raw_Data!G1312 -> 465.04 | E7: =Raw_Data!G1376 -> 367.35 | F7: =(E7-D7)/D7*100 -> -21.006795 | G7: =RANK(F7,$F$2:$F$9,0) -> 8
A8: TSLA | B8: Consumer Discretionary | C8: 2024-Q1 | D8: =Raw_Data!G1574 -> 226.75 | E8: =Raw_Data!G1638 -> 182.35 | F8: =(E8-D8)/D8*100 -> -19.581036 | G8: =RANK(F8,$F$2:$F$9,0) -> 7
A9: XOM | B9: Energy | C9: 2024-Q1 | D9: =Raw_Data!G1836 -> 100.86 | E9: =Raw_Data!G1900 -> 104 | F9: =(E9-D9)/D9*100 -> 3.1132263 | G9: =RANK(F9,$F$2:$F$9,0) -> 2
A10: AAPL | B10: Technology | C10: 2024-Q2 | D10: =Raw_Data!G67 -> 245.74 | E10: =Raw_Data!G131 -> 259.87 | F10: =(E10-D10)/D10*100 -> 5.7499797 | G10: =RANK(F10,$F$10:$F$17,0) -> 5
A11: JNJ | B11: Healthcare | C11: 2024-Q2 | D11: =Raw_Data!G329 -> 127.62 | E11: =Raw_Data!G393 -> 112.94 | F11: =(E11-D11)/D11*100 -> -11.502899 | G11: =RANK(F11,$F$10:$F$17,0) -> 8
A12: JPM | B12: Financials | C12: 2024-Q2 | D12: =Raw_Data!G591 -> 150.3 | E12: =Raw_Data!G655 -> 149 | F12: =(E12-D12)/D12*100 -> -0.86493679 | G12: =RANK(F12,$F$10:$F$17,0) -> 7
A13: KO | B13: Consumer Staples | C13: 2024-Q2 | D13: =Raw_Data!G853 -> 51.17 | E13: =Raw_Data!G917 -> 56.19 | F13: =(E13-D13)/D13*100 -> 9.8104358 | G13: =RANK(F13,$F$10:$F$17,0) -> 4
A14: MSFT | B14: Technology | C14: 2024-Q2 | D14: =Raw_Data!G1115 -> 317.54 | E14: =Raw_Data!G1179 -> 432.74 | F14: =(E14-D14)/D14*100 -> 36.278894 | G14: =RANK(F14,$F$10:$F$17,0) -> 1
A15: NVDA | B15: Technology | C15: 2024-Q2 | D15: =Raw_Data!G1377 -> 359.65 | E15: =Raw_Data!G1441 -> 413.35 | F15: =(E15-D15)/D15*100 -> 14.931183 | G15: =RANK(F15,$F$10:$F$17,0) -> 2
A16: TSLA | B16: Consumer Discretionary | C16: 2024-Q2 | D16: =Raw_Data!G1639 -> 184.87 | E16: =Raw_Data!G1703 -> 188.44 | F16: =(E16-D16)/D16*100 -> 1.9310867 | G16: =RANK(F16,$F$10:$F$17,0) -> 6
A17: XOM | B17: Energy | C17: 2024-Q2 | D17: =Raw_Data!G1901 -> 102.62 | E17: =Raw_Data!G1965 -> 114.62 | F17: =(E17-D17)/D17*100 -> 11.693627 | G17: =RANK(F17,$F$10:$F$17,0) -> 3
A18: AAPL | B18: Technology | C18: 2024-Q3 | D18: =Raw_Data!G132 -> 256.08 | E18: =Raw_Data!G197 -> 262.16 | F18: =(E18-D18)/D18*100 -> 2.374258 | G18: =RANK(F18,$F$18:$F$25,0) -> 3
A19: JNJ | B19: Healthcare | C19: 2024-Q3 | D19: =Raw_Data!G394 -> 111.46 | E19: =Raw_Data!G459 -> 113.11 | F19: =(E19-D19)/D19*100 -> 1.4803517 | G19: =RANK(F19,$F$18:$F$25,0) -> 4
A20: JPM | B20: Financials | C20: 2024-Q3 | D20: =Raw_Data!G656 -> 148.11 | E20: =Raw_Data!G721 -> 148 | F20: =(E20-D20)/D20*100 -> -0.074269124 | G20: =RANK(F20,$F$18:$F$25,0) -> 5
A21: KO | B21: Consumer Staples | C21: 2024-Q3 | D21: =Raw_Data!G918 -> 57.05 | E21: =Raw_Data!G983 -> 53.08 | F21: =(E21-D21)/D21*100 -> -6.9588081 | G21: =RANK(F21,$F$18:$F$25,0) -> 7
A22: MSFT | B22: Technology | C22: 2024-Q3 | D22: =Raw_Data!G1180 -> 427.96 | E22: =Raw_Data!G1245 -> 416.15 | F22: =(E22-D22)/D22*100 -> -2.7596037 | G22: =RANK(F22,$F$18:$F$25,0) -> 6
A23: NVDA | B23: Technology | C23: 2024-Q3 | D23: =Raw_Data!G1442 -> 408.49 | E23: =Raw_Data!G1507 -> 434.06 | F23: =(E23-D23)/D23*100 -> 6.2596392 | G23: =RANK(F23,$F$18:$F$25,0) -> 1
A24: TSLA | B24: Consumer Discretionary | C24: 2024-Q3 | D24: =Raw_Data!G1704 -> 178.82 | E24: =Raw_Data!G1769 -> 124.09 | F24: =(E24-D24)/D24*100 -> -30.606196 | G24: =RANK(F24,$F$18:$F$25,0) -> 8
A25: XOM | B25: Energy | C25: 2024-Q3 | D25: =Raw_Data!G1966 -> 117.11 | E25: =Raw_Data!G2031 -> 122.79 | F25: =(E25-D25)/D25*100 -> 4.8501409 | G25: =RANK(F25,$F$18:$F$25,0) -> 2
A26: AAPL | B26: Technology | C26: 2024-Q4 | D26: =Raw_Data!G198 -> 263.09 | E26: =Raw_Data!G263 -> 304.53 | F26: =(E26-D26)/D26*100 -> 15.751264 | G26: =RANK(F26,$F$26:$F$33,0) -> 3
A27: JNJ | B27: Healthcare | C27: 2024-Q4 | D27: =Raw_Data!G460 -> 111.39 | E27: =Raw_Data!G525 -> 112.61 | F27: =(E27-D27)/D27*100 -> 1.0952509 | G27: =RANK(F27,$F$26:$F$33,0) -> 6
A28: JPM | B28: Financials | C28: 2024-Q4 | D28: =Raw_Data!G722 -> 153.21 | E28: =Raw_Data!G787 -> 172.24 | F28: =(E28-D28)/D28*100 -> 12.42086 | G28: =RANK(F28,$F$26:$F$33,0) -> 4
A29: KO | B29: Consumer Staples | C29: 2024-Q4 | D29: =Raw_Data!G984 -> 53.56 | E29: =Raw_Data!G1049 -> 50.64 | F29: =(E29-D29)/D29*100 -> -5.4518297 | G29: =RANK(F29,$F$26:$F$33,0) -> 7
A30: MSFT | B30: Technology | C30: 2024-Q4 | D30: =Raw_Data!G1246 -> 412.65 | E30: =Raw_Data!G1311 -> 478.06 | F30: =(E30-D30)/D30*100 -> 15.851206 | G30: =RANK(F30,$F$26:$F$33,0) -> 2
A31: NVDA | B31: Technology | C31: 2024-Q4 | D31: =Raw_Data!G1508 -> 446.68 | E31: =Raw_Data!G1573 -> 730 | F31: =(E31-D31)/D31*100 -> 63.427957 | G31: =RANK(F31,$F$26:$F$33,0) -> 1
A32: TSLA | B32: Consumer Discretionary | C32: 2024-Q4 | D32: =Raw_Data!G1770 -> 121.95 | E32: =Raw_Data!G1835 -> 125.26 | F32: =(E32-D32)/D32*100 -> 2.7142271 | G32: =RANK(F32,$F$26:$F$33,0) -> 5
A33: XOM | B33: Energy | C33: 2024-Q4 | D33: =Raw_Data!G2032 -> 122.92 | E33: =Raw_Data!G2097 -> 98.43 | F33: =(E33-D33)/D33*100 -> -19.923527 | G33: =RANK(F33,$F$26:$F$33,0) -> 8
A37: Quarter | B37: AAPL | C37: JNJ | D37: JPM | E37: KO | F37: MSFT | G37: NVDA | H37: TSLA | I37: XOM
A38: 2024-Q1 | B38: =INDEX($F$2:$F$9,MATCH(B$37,$A$2:$A$9,0)) -> 39.318434 | C38: =INDEX($F$2:$F$9,MATCH(C$37,$A$2:$A$9,0)) -> -19.29759 | D38: =INDEX($F$2:$F$9,MATCH(D$37,$A$2:$A$9,0)) -> -0.34309844 | E38: =INDEX($F$2:$F$9,MATCH(E$37,$A$2:$A$9,0)) -> -12.814371 | F38: =INDEX($F$2:$F$9,MATCH(F$37,$A$2:$A$9,0)) -> -3.5553435 | G38: =INDEX($F$2:$F$9,MATCH(G$37,$A$2:$A$9,0)) -> -21.006795 | H38: =INDEX($F$2:$F$9,MATCH(H$37,$A$2:$A$9,0)) -> -19.581036 | I38: =INDEX($F$2:$F$9,MATCH(I$37,$A$2:$A$9,0)) -> 3.1132263
A39: 2024-Q2 | B39: =INDEX($F$10:$F$17,MATCH(B$37,$A$10:$A$17,0)) -> 5.7499797 | C39: =INDEX($F$10:$F$17,MATCH(C$37,$A$10:$A$17,0)) -> -11.502899 | D39: =INDEX($F$10:$F$17,MATCH(D$37,$A$10:$A$17,0)) -> -0.86493679 | E39: =INDEX($F$10:$F$17,MATCH(E$37,$A$10:$A$17,0)) -> 9.8104358 | F39: =INDEX($F$10:$F$17,MATCH(F$37,$A$10:$A$17,0)) -> 36.278894 | G39: =INDEX($F$10:$F$17,MATCH(G$37,$A$10:$A$17,0)) -> 14.931183 | H39: =INDEX($F$10:$F$17,MATCH(H$37,$A$10:$A$17,0)) -> 1.9310867 | I39: =INDEX($F$10:$F$17,MATCH(I$37,$A$10:$A$17,0)) -> 11.693627
A40: 2024-Q3 | B40: =INDEX($F$18:$F$25,MATCH(B$37,$A$18:$A$25,0)) -> 2.374258 | C40: =INDEX($F$18:$F$25,MATCH(C$37,$A$18:$A$25,0)) -> 1.4803517 | D40: =INDEX($F$18:$F$25,MATCH(D$37,$A$18:$A$25,0)) -> -0.074269124 | E40: =INDEX($F$18:$F$25,MATCH(E$37,$A$18:$A$25,0)) -> -6.9588081 | F40: =INDEX($F$18:$F$25,MATCH(F$37,$A$18:$A$25,0)) -> -2.7596037 | G40: =INDEX($F$18:$F$25,MATCH(G$37,$A$18:$A$25,0)) -> 6.2596392 | H40: =INDEX($F$18:$F$25,MATCH(H$37,$A$18:$A$25,0)) -> -30.606196 | I40: =INDEX($F$18:$F$25,MATCH(I$37,$A$18:$A$25,0)) -> 4.8501409
A41: 2024-Q4 | B41: =INDEX($F$26:$F$33,MATCH(B$37,$A$26:$A$33,0)) -> 15.751264 | C41: =INDEX($F$26:$F$33,MATCH(C$37,$A$26:$A$33,0)) -> 1.0952509 | D41: =INDEX($F$26:$F$33,MATCH(D$37,$A$26:$A$33,0)) -> 12.42086 | E41: =INDEX($F$26:$F$33,MATCH(E$37,$A$26:$A$33,0)) -> -5.4518297 | F41: =INDEX($F$26:$F$33,MATCH(F$37,$A$26:$A$33,0)) -> 15.851206 | G41: =INDEX($F$26:$F$33,MATCH(G$37,$A$26:$A$33,0)) -> 63.427957 | H41: =INDEX($F$26:$F$33,MATCH(H$37,$A$26:$A$33,0)) -> 2.7142271 | I41: =INDEX($F$26:$F$33,MATCH(I$37,$A$26:$A$33,0)) -> -19.923527

Sheet Sector_Trend
A1: Sector | B1: 2024-01 | C1: 2024-02 | D1: 2024-03 | E1: 2024-04 | F1: 2024-05 | G1: 2024-06 | H1: 2024-07 | I1: 2024-08 | J1: 2024-09 | K1: 2024-10 | L1: 2024-11 | M1: 2024-12
A2: Consumer Discretionary | B2: =AVERAGEIFS(Raw_Data!$J$2:$J$2097,Raw_Data!$B$2:$B$2097,$A2,Raw_Data!$O$2:$O$2097,B$1) -> 0.19583892 | C2: =AVERAGEIFS(Raw_Data!$J$2:$J$2097,Raw_Data!$B$2:$B$2097,$A2,Raw_Data!$O$2:$O$2097,C$1) -> -0.81038084 | D2: =AVERAGEIFS(Raw_Data!$J$2:$J$2097,Raw_Data!$B$2:$B$2097,$A2,Raw_Data!$O$2:$O$2097,D$1) -> -0.21768457 | E2: =AVERAGEIFS(Raw_Data!$J$2:$J$2097,Raw_Data!$B$2:$B$2097,$A2,Raw_Data!$O$2:$O$2097,E$1) -> -0.8772816 | F2: =AVERAGEIFS(Raw_Data!$J$2:$J$2097,Raw_Data!$B$2:$B$2097,$A2,Raw_Data!$O$2:$O$2097,F$1) -> 1.3849477 | G2: =AVERAGEIFS(Raw_Data!$J$2:$J$2097,Raw_Data!$B$2:$B$2097,$A2,Raw_Data!$O$2:$O$2097,G$1) -> -0.2696109 | H2: =AVERAGEIFS(Raw_Data!$J$2:$J$2097,Raw_Data!$B$2:$B$2097,$A2,Raw_Data!$O$2:$O$2097,H$1) -> -0.72813805 | I2: =AVERAGEIFS(Raw_Data!$J$2:$J$2097,Raw_Data!$B$2:$B$2097,$A2,Raw_Data!$O$2:$O$2097,I$1) -> 0.096208671 | ... M2: =AVERAGEIFS(Raw_Data!$J$2:$J$2097,Raw_Data!$B$2:$B$2097,$A2,Raw_Data!$O$2:$O$2097,M$1) -> 0.18520334
A3: Consumer Staples | B3: =AVERAGEIFS(Raw_Data!$J$2:$J$2097,Raw_Data!$B$2:$B$2097,$A3,Raw_Data!$O$2:$O$2097,B$1) -> -0.021716418 | C3: =AVERAGEIFS(Raw_Data!$J$2:$J$2097,Raw_Data!$B$2:$B$2097,$A3,Raw_Data!$O$2:$O$2097,C$1) -> -0.50260401 | D3: =AVERAGEIFS(Raw_Data!$J$2:$J$2097,Raw_Data!$B$2:$B$2097,$A3,Raw_Data!$O$2:$O$2097,D$1) -> -0.097169793 | E3: =AVERAGEIFS(Raw_Data!$J$2:$J$2097,Raw_Data!$B$2:$B$2097,$A3,Raw_Data!$O$2:$O$2097,E$1) -> 0.32856942 | F3: =AVERAGEIFS(Raw_Data!$J$2:$J$2097,Raw_Data!$B$2:$B$2097,$A3,Raw_Data!$O$2:$O$2097,F$1) -> 0.10239274 | G3: =AVERAGEIFS(Raw_Data!$J$2:$J$2097,Raw_Data!$B$2:$B$2097,$A3,Raw_Data!$O$2:$O$2097,G$1) -> 0.037311272 | H3: =AVERAGEIFS(Raw_Data!$J$2:$J$2097,Raw_Data!$B$2:$B$2097,$A3,Raw_Data!$O$2:$O$2097,H$1) -> 0.10020624 | I3: =AVERAGEIFS(Raw_Data!$J$2:$J$2097,Raw_Data!$B$2:$B$2097,$A3,Raw_Data!$O$2:$O$2097,I$1) -> -0.30013007 | ... M3: =AVERAGEIFS(Raw_Data!$J$2:$J$2097,Raw_Data!$B$2:$B$2097,$A3,Raw_Data!$O$2:$O$2097,M$1) -> -0.0068961026
A4: Energy | B4: =AVERAGEIFS(Raw_Data!$J$2:$J$2097,Raw_Data!$B$2:$B$2097,$A4,Raw_Data!$O$2:$O$2097,B$1) -> 0.54330575 | C4: =AVERAGEIFS(Raw_Data!$J$2:$J$2097,Raw_Data!$B$2:$B$2097,$A4,Raw_Data!$O$2:$O$2097,C$1) -> -0.1451865 | D4: =AVERAGEIFS(Raw_Data!$J$2:$J$2097,Raw_Data!$B$2:$B$2097,$A4,Raw_Data!$O$2:$O$2097,D$1) -> -0.22815728 | E4: =AVERAGEIFS(Raw_Data!$J$2:$J$2097,Raw_Data!$B$2:$B$2097,$A4,Raw_Data!$O$2:$O$2097,E$1) -> 0.2193377 | F4: =AVERAGEIFS(Raw_Data!$J$2:$J$2097,Raw_Data!$B$2:$B$2097,$A4,Raw_Data!$O$2:$O$2097,F$1) -> 0.68397531 | G4: =AVERAGEIFS(Raw_Data!$J$2:$J$2097,Raw_Data!$B$2:$B$2097,$A4,Raw_Data!$O$2:$O$2097,G$1) -> -0.44733155 | H4: =AVERAGEIFS(Raw_Data!$J$2:$J$2097,Raw_Data!$B$2:$B$2097,$A4,Raw_Data!$O$2:$O$2097,H$1) -> 0.47894708 | I4: =AVERAGEIFS(Raw_Data!$J$2:$J$2097,Raw_Data!$B$2:$B$2097,$A4,Raw_Data!$O$2:$O$2097,I$1) -> -0.10079526 | ... M4: =AVERAGEIFS(Raw_Data!$J$2:$J$2097,Raw_Data!$B$2:$B$2097,$A4,Raw_Data!$O$2:$O$2097,M$1) -> -0.24395981
A5: Financials | B5: =AVERAGEIFS(Raw_Data!$J$2:$J$2097,Raw_Data!$B$2:$B$2097,$A5,Raw_Data!$O$2:$O$2097,B$1) -> 0.38133277 | C5: =AVERAGEIFS(Raw_Data!$J$2:$J$2097,Raw_Data!$B$2:$B$2097,$A5,Raw_Data!$O$2:$O$2097,C$1) -> -0.39325913 | D5: =AVERAGEIFS(Raw_Data!$J$2:$J$2097,Raw_Data!$B$2:$B$2097,$A5,Raw_Data!$O$2:$O$2097,D$1) -> 0.026166452 | E5: =AVERAGEIFS(Raw_Data!$J$2:$J$2097,Raw_Data!$B$2:$B$2097,$A5,Raw_Data!$O$2:$O$2097,E$1) -> 0.3130952 | F5: =AVERAGEIFS(Raw_Data!$J$2:$J$2097,Raw_Data!$B$2:$B$2097,$A5,Raw_Data!$O$2:$O$2097,F$1) -> 0.18620258 | G5: =AVERAGEIFS(Raw_Data!$J$2:$J$2097,Raw_Data!$B$2:$B$2097,$A5,Raw_Data!$O$2:$O$2097,G$1) -> -0.56076609 | H5: =AVERAGEIFS(Raw_Data!$J$2:$J$2097,Raw_Data!$B$2:$B$2097,$A5,Raw_Data!$O$2:$O$2097,H$1) -> -0.17003831 | I5: =AVERAGEIFS(Raw_Data!$J$2:$J$2097,Raw_Data!$B$2:$B$2097,$A5,Raw_Data!$O$2:$O$2097,I$1) -> -0.19188572 | ... M5: =AVERAGEIFS(Raw_Data!$J$2:$J$2097,Raw_Data!$B$2:$B$2097,$A5,Raw_Data!$O$2:$O$2097,M$1) -> 0.037125136
A6: Healthcare | B6: =AVERAGEIFS(Raw_Data!$J$2:$J$2097,Raw_Data!$B$2:$B$2097,$A6,Raw_Data!$O$2:$O$2097,B$1) -> -0.12903517 | C6: =AVERAGEIFS(Raw_Data!$J$2:$J$2097,Raw_Data!$B$2:$B$2097,$A6,Raw_Data!$O$2:$O$2097,C$1) -> -0.20533448 | D6: =AVERAGEIFS(Raw_Data!$J$2:$J$2097,Raw_Data!$B$2:$B$2097,$A6,Raw_Data!$O$2:$O$2097,D$1) -> -0.63374664 | E6: =AVERAGEIFS(Raw_Data!$J$2:$J$2097,Raw_Data!$B$2:$B$2097,$A6,Raw_Data!$O$2:$O$2097,E$1) -> -0.007655813 | F6: =AVERAGEIFS(Raw_Data!$J$2:$J$2097,Raw_Data!$B$2:$B$2097,$A6,Raw_Data!$O$2:$O$2097,F$1) -> -0.40101633 | G6: =AVERAGEIFS(Raw_Data!$J$2:$J$2097,Raw_Data!$B$2:$B$2097,$A6,Raw_Data!$O$2:$O$2097,G$1) -> -0.194419 | H6: =AVERAGEIFS(Raw_Data!$J$2:$J$2097,Raw_Data!$B$2:$B$2097,$A6,Raw_Data!$O$2:$O$2097,H$1) -> -0.3109369 | I6: =AVERAGEIFS(Raw_Data!$J$2:$J$2097,Raw_Data!$B$2:$B$2097,$A6,Raw_Data!$O$2:$O$2097,I$1) -> 0.2329888 | ... M6: =AVERAGEIFS(Raw_Data!$J$2:$J$2097,Raw_Data!$B$2:$B$2097,$A6,Raw_Data!$O$2:$O$2097,M$1) -> 0.029854572
A7: Technology | B7: =AVERAGEIFS(Raw_Data!$J$2:$J$2097,Raw_Data!$B$2:$B$2097,$A7,Raw_Data!$O$2:$O$2097,B$1) -> -0.089162214 | C7: =AVERAGEIFS(Raw_Data!$J$2:$J$2097,Raw_Data!$B$2:$B$2097,$A7,Raw_Data!$O$2:$O$2097,C$1) -> 0.071690653 | D7: =AVERAGEIFS(Raw_Data!$J$2:$J$2097,Raw_Data!$B$2:$B$2097,$A7,Raw_Data!$O$2:$O$2097,D$1) -> 0.19555516 | E7: =AVERAGEIFS(Raw_Data!$J$2:$J$2097,Raw_Data!$B$2:$B$2097,$A7,Raw_Data!$O$2:$O$2097,E$1) -> -0.007901009 | F7: =AVERAGEIFS(Raw_Data!$J$2:$J$2097,Raw_Data!$B$2:$B$2097,$A7,Raw_Data!$O$2:$O$2097,F$1) -> 0.23769288 | G7: =AVERAGEIFS(Raw_Data!$J$2:$J$2097,Raw_Data!$B$2:$B$2097,$A7,Raw_Data!$O$2:$O$2097,G$1) -> 0.63505612 | H7: =AVERAGEIFS(Raw_Data!$J$2:$J$2097,Raw_Data!$B$2:$B$2097,$A7,Raw_Data!$O$2:$O$2097,H$1) -> 0.34521305 | I7: =AVERAGEIFS(Raw_Data!$J$2:$J$2097,Raw_Data!$B$2:$B$2097,$A7,Raw_Data!$O$2:$O$2097,I$1) -> -0.3503644 | ... M7: =AVERAGEIFS(Raw_Data!$J$2:$J$2097,Raw_Data!$B$2:$B$2097,$A7,Raw_Data!$O$2:$O$2097,M$1) -> 0.49351779

Sheet Volume_Spike
A1: Ticker | B1: Date | C1: Volume | D1: Avg_Volume_30D | E1: Rasio_vs_Rata2
A2: NVDA | B2: 2024-11-12 | C2: 41304838 | D2: 7733846 | E2: 5.34
A3: JNJ | B3: 2024-05-22 | C3: 21169490 | D3: 4164438 | E3: 5.08
A4: JNJ | B4: 2024-03-13 | C4: 20955666 | D4: 4201782 | E4: 4.99
A5: MSFT | B5: 2024-07-25 | C5: 35810613 | D5: 8123003 | E5: 4.41
A6: AAPL | B6: 2024-02-29 | C6: 37250795 | D6: 8708258 | E6: 4.28
A7: NVDA | B7: 2024-03-28 | C7: 32701697 | D7: 7751418 | E7: 4.22
A8: NVDA | B8: 2024-04-05 | C8: 35073548 | D8: 8706319 | E8: 4.03
A9: TSLA | B9: 2024-12-05 | C9: 19064715 | D9: 4779121 | E9: 3.99
A10: NVDA | B10: 2024-08-08 | C10: 33996713 | D10: 8731405 | E10: 3.89
A11: TSLA | B11: 2024-11-21 | C11: 15225167 | D11: 3947507 | E11: 3.86
A12: KO | B12: 2024-04-02 | C12: 15750519 | D12: 4205411 | E12: 3.75
A13: TSLA | B13: 2024-02-12 | C13: 19719175 | D13: 5270422 | E13: 3.74
... A21: JNJ | B21: 2024-07-10 | C21: 13136427 | D21: 4079589 | E21: 3.22
